Workbook

Sheet Итоговый лист
A1: Доходы | D1: Расходы | H1: Примечание
A2: Входные билеты | C2: 52500 | D2: Промоутеры | F2: =Промоутеры!F14 -> 50500 | H2: Долг безнал: | I2: Долг нал:
A3: Бар | C3: 35560 | D3: Такси | F3: ='Лист выплат'!D70 -> 0 | H3: Д3 Даша-2300 | I3: Д3 Даша-6750
A4: Консумация Бара | C4: 83500 | D4: Промо | F4: ='Лист выплат'!G68 -> 8000 | H4: Д5 Софья-22000 | I4: Д5 Софья-500
A5: Консумация кухни | D5: Ставка менеджера | F5: ='Лист выплат'!D59 -> 4000 | H5: Д9 Лилит-8850 | I5: Д9 Лилит-2500
A6: Crazy Menu | C6: 239500 | D6: Ставка танцовщиц | F6: =SUM('Лист выплат'!D3:D17) -> 7500 | H6: Д11 Дана-18300 | I6: Д11 Дана-6250
A7: Общий чай | C7: 96000 | D7: Ставка хостес | F7: =SUM('Лист выплат'!D39:D43) -> 8000 | H7: Д18 Аннет-34200 | I7: Д18 Аннет-500
A8: Overtime | D8: Ставка официантов | F8: =SUM('Лист выплат'!D30:D37) -> 3000 | H8: Д21 Банни-1250 | I8: Д21 Банни-8250
A9: Кальяны | C9: 46000 | D9: Ставка бармена | F9: =SUM('Лист выплат'!D52:D55) -> 7000 | H9: Д66 Алиса-29700 | I9: Д66 Алиса-2850
A10: Шары | D10: Ставка патигерл | F10: =SUM('Лист выплат'!D19:D28) -> 0 | H10: Оф3 Каталина-1050 | I10: Оф3 Каталина-400
A11: Штрафы | D11: Выплата админа | F11: =SUM('Лист выплат'!D60:D61) -> 15000 | H11: Оф4 Ника-750 | I11: Оф4 Ника-4400
A12: Стафф | D12: Выплата стажерам | F12: =SUM('Лист выплат'!D45:D51) -> 0 | H12: Н3 Влада-1000 | I12: Н4 Тати-3000
A13: Стафф кальян | D13: Выплата СБ | F13: =SUM('Лист выплат'!D64:D66) -> 12000 | H13: Н4 Тати-1500 | I13: Б4 Камила-4000
A14: Доход клуба | C14: 22800 | D14: CRZ - меню | F14: ='Лист выплат'!H68 -> 108600 | H14: Б4 Камила-1600 | I14: Б52 Даня-4000
A15: Сервисный сбор | C15: 12110 | D15: Консумация | F15: ='Лист выплат'!I68 -> 21900 | H15: Б52 Даня-3000 | I15: К21 Маратик-7700
A16: Итого | C16: =SUM(C2:C15) -> 587970 | D16: Чаевые | F16: ='Лист выплат'!J68 -> 68450 | H16: К21 Маратик-4700 | I16: Дж14 Сергей-4200
A17: плюс по кассе | C17: 0 | D17: Ставка кальянщика | F17: =SUM('Лист выплат'!D56:D57) -> 0 | H17: Дж14 Сергей-3000 | I17: А17 Юля-16700
A18: Итого за смену | C18: =SUM(C16:C17) -> 587970 | D18: Ставка диджея | F18: ='Лист выплат'!D58 -> 3000 | H18: М69 Марина-5850 | I18: СБ Женя Егоров-350
D19: Уборщица | F19: =SUM('Лист выплат'!D67) -> 2000 | H19: А17 Юля-14850 | I19: СБ Дима Песков-350
D20: Стилист/визажист | F20: ='Лист выплат'!D74 -> 1000 | H20: СБ Женя Егоров-2950 | I20: СБ Денис Ермаков-300
A21: Входные билеты | D21: % таксистам | F21: ='Лист выплат'!D71 -> 0 | H21: СБ Дима Песков-2900 | I21: Стилист Зарема-500
A22: цена | B22: кол-во | C22: сумма | D22: Прочие расходы | F22: ='Лист выплат'!D72 -> 0 | H22: СБ Денис Ермаков-3000 | I22: Визажист Оксана-500
A23: Бесплатно | B23: 4 | D23: 5% Р9 | F23: ='Лист выплат'!D73 -> 300 | H23: Р1 Дима-2500 | I23: Р1 Дима-13000
A24: 1000 | D24: 5% со столов | F24: ='Лист выплат'!F68 -> 5950 | H24: Р15 Гриша-1000 | I24: Р9 Рома-5000
A25: 1500 | B25: 7 | C25: 10500 | D25: 5% промоутеров | F25: =SUM('Лист выплат'!D75) -> 11100 | H25: Р17 Ильяз-3500 | I25: Р10 Дима-1000
A26: 2000 | B26: 18 | C26: 36000 | D26: % Жени | F26: =SUM('Лист выплат'!D76) -> 0 | H26: ИТОГО: 169750 | I26: Р15 Гриша-10000
A27: 3000 | B27: 2 | C27: 6000 | D27: Ставка ЛМ | F27: =SUM('Лист выплат'!D62:D63) -> 0 | I27: Р17 Ильяз-20500
A28: 4000 | D28: 5% ЛМ | F28: ='Лист выплат'!E68 -> 0 | I28: Р29 Сергей-1000
A29: 5000 | D29: Итого | F29: =SUM(F2:F28) -> 337300 | I29: %Р1-2750
I30: %Р15-3250
A31: ИТОГО: | B31: =SUM(B23:B30) -> 31 | C31: =SUM(C24:C30) -> 52500 | D31: Инкассация | I31: %Р9-300
E32: кол-во | F32: курс | G32: сумма | I32: %Р17-5100
A33: Наличные | C33: 125550 | D33: Рубль | G33: 86900 | I33: ИТОГО: 135900
A34: Сбербанк | C34: 303580 | D34: Доллар | E34: 100 | F34: 70 | G34: 7000
A35: СБП Сбербанк | C35: 158840 | D35: Евро
A36: Банк Тинькофф
A37: СБП Тинькофф
A40: ИТОГО КАССА: | C40: 500590
A41: ИТОГО: | C41: =SUM(C33:C39) -> 587970 | D41: Итого | G41: =SUM(G33:G40) -> 93900
A42: статистика персонала | H42: итого
...

Sheet Лист выплат
A1: № | C1: ФАМИЛИЯ | D1: СТАВКА | E1: 5% ЛМ | F1: 0.05 | G1: ПРОМО | H1: CRAZY MENU | I1: Консумация | J1: ЧАЕВЫЕ | K1: ШТРАФЫ | L1: ИТОГО выплат по смене | M1: ДОЛГ | N1: ДОЛГ НАЛ | O1: к выплате
A2: Танцовщицы
A3: Д | B3: 3 | C3: Даша | D3: 2500 | H3: 5350 | I3: =SUM('крейзи консум новый'!X4:X5) -> 1200 | J3: =SUM('Общий чай'!S3:S4)*0.5 -> 0 | L3: =D3+G3+H3+I3+J3-K3 -> 9050 | M3: 2300 | N3: 6750 | O3: =L3-M3-N3 -> 0
A4: Д | B4: 5 | C4: Софья | H4: =SUM('крейзи консум новый'!C6:C7) -> 16200 | I4: =SUM('крейзи консум новый'!X6:X7) -> 3800 | J4: =SUM('Общий чай'!S5:S6)*0.5 -> 2500 | L4: =D4+G4+H4+I4+J4-K4 -> 22500 | M4: 22000 | N4: 500 | O4: =L4-M4-N4 -> 0
A5: Д | B5: 9 | C5: Лилит | D5: 2500 | H5: =SUM('крейзи консум новый'!C8:C9) -> 8550 | I5: =SUM('крейзи консум новый'!X8:X9) -> 300 | J5: =SUM('Общий чай'!S7:S8)*0.5 -> 0 | L5: =D5+G5+H5+I5+J5-K5 -> 11350 | M5: 8850 | N5: 2500 | O5: =L5-M5-N5 -> 0
A6: Д | B6: 11 | C6: Дана | H6: =SUM('крейзи консум новый'!C10:C11) -> 20450 | I6: =SUM('крейзи консум новый'!X10:X11) -> 600 | J6: =SUM('Общий чай'!S9:S10)*0.5 -> 3500 | L6: =D6+G6+H6+I6+J6-K6 -> 24550 | M6: 18300 | N6: 6250 | O6: =L6-M6-N6 -> 0
A7: Д | B7: 18 | C7: Аннет | H7: =SUM('крейзи консум новый'!C12:C13) -> 34200 | I7: =SUM('крейзи консум новый'!X12:X13) -> 0 | J7: =SUM('Общий чай'!S11:S12)*0.5 -> 500 | L7: =D7+G7+H7+I7+J7-K7 -> 34700 | M7: 34200 | N7: 500 | O7: =L7-M7-N7 -> 0
A8: Д | B8: 21 | C8: Банни | D8: 2500 | H8: =SUM('крейзи консум новый'!C14:C15) -> 0 | I8: 2250 | J8: =SUM('Общий чай'!S12:S13)*0.5 -> 4750 | L8: =D8+G8+H8+I8+J8-K8 -> 9500 | M8: 1250 | N8: 8250 | O8: =L8-M8-N8 -> 0
A9: Д | B9: 66 | C9: Алиса | H9: =SUM('крейзи консум новый'!C16:C17) -> 23850 | I9: 1700 | J9: =SUM('Общий чай'!S15:S16)*0.5 -> 7000 | L9: =D9+G9+H9+I9+J9-K9 -> 32550 | M9: 29700 | N9: 2850 | O9: =L9-M9-N9 -> 0
A10: Д | H10: =SUM('крейзи консум новый'!C18:C19) -> 0 | I10: =SUM('крейзи консум новый'!X18:X19) -> 0 | J10: =SUM('Общий чай'!S17:S18)*0.5 -> 0 | L10: =D10+G10+H10+I10+J10-K10 -> 0 | O10: =L10-M10-N10 -> 0
A11: Д | H11: =SUM('крейзи консум новый'!C20:C21) -> 0 | I11: =SUM('крейзи консум новый'!X20:X21) -> 0 | J11: =SUM('Общий чай'!S19:S20)*0.5 -> 0 | L11: =D11+G11+H11+I11+J11-K11 -> 0 | O11: =L11-M11-N11 -> 0
A12: Д | H12: =SUM('крейзи консум новый'!C22:C23) -> 0 | I12: =SUM('крейзи консум новый'!X22:X23) -> 0 | J12: =SUM('Общий чай'!S21:S22)*0.5 -> 0 | L12: =D12+G12+H12+I12+J12-K12 -> 0 | O12: =L12-M12-N12 -> 0
A13: Д | H13: =SUM('крейзи консум новый'!C24:C25) -> 0 | I13: =SUM('крейзи консум новый'!X24:X25) -> 0 | J13: =SUM('Общий чай'!S23:S24)*0.5 -> 0 | L13: =D13+G13+H13+I13+J13-K13 -> 0 | O13: =L13-M13-N13 -> 0
A14: Д | H14: =SUM('крейзи консум новый'!C26:C27) -> 0 | I14: =SUM('крейзи консум новый'!X26:X27) -> 0 | J14: =SUM('Общий чай'!S25:S26)*0.5 -> 0 | L14: =D14+G14+H14+I14+J14-K14 -> 0 | O14: =L14-M14-N14 -> 0
A15: Д | H15: =SUM('крейзи консум новый'!C28:C29) -> 0 | I15: =SUM('крейзи консум новый'!X28:X29) -> 0 | J15: =SUM('Общий чай'!S27:S28)*0.5 -> 0 | L15: =D15+G15+H15+I15+J15-K15 -> 0 | O15: =L15-M15-N15 -> 0
A16: Д | H16: =SUM('крейзи консум новый'!C30:C31) -> 0 | I16: =SUM('крейзи консум новый'!X30:X31) -> 0 | J16: =SUM('Общий чай'!S29:S30)*0.5 -> 0 | L16: =D16+G16+H16+I16+J16-K16 -> 0 | O16: =L16-M16-N16 -> 0
A17: Д | H17: =SUM('крейзи консум новый'!C32:C33) -> 0 | I17: =SUM('крейзи консум новый'!X32:X33) -> 0 | J17: =SUM('Общий чай'!S31:S32)*0.5 -> 0 | L17: =D17+G17+H17+I17+J17-K17 -> 0 | O17: =L17-M17-N17 -> 0
A18: Патигерл
A19: Г | H19: =SUM('крейзи консум новый'!C35:C36) -> 0 | I19: =SUM('крейзи консум новый'!X35:X36) -> 0 | J19: =SUM('Общий чай'!S34:S35)*0.5 -> 0 | L19: =D19+F19+G19+H19+I19+J19-K19 -> 0 | O19: =L19-M19-N19 -> 0
A20: Г | H20: =SUM('крейзи консум новый'!C37:C38) -> 0 | I20: =SUM('крейзи консум новый'!X37:X38) -> 0 | J20: =SUM('Общий чай'!S36:S37)*0.5 -> 0 | L20: =D20+F20+G20+H20+I20+J20-K20 -> 0 | O20: =L20-M20-N20 -> 0
A21: Г | H21: =SUM('крейзи консум новый'!C39:C40) -> 0 | I21: =SUM('крейзи консум новый'!X39:X40) -> 0 | J21: =SUM('Общий чай'!S38:S39)*0.5 -> 0 | L21: =D21+F21+G21+H21+I21+J21-K21 -> 0 | O21: =L21-M21-N21 -> 0
A22: Г | H22: =SUM('крейзи консум новый'!C41:C42) -> 0 | I22: =SUM('крейзи консум новый'!X41:X42) -> 0 | J22: =SUM('Общий чай'!S40:S41)*0.5 -> 0 | L22: =D22+F22+G22+H22+I22+J22-K22 -> 0 | O22: =L22-M22-N22 -> 0
A23: Г | H23: =SUM('крейзи консум новый'!C43:C44) -> 0 | I23: =SUM('крейзи консум новый'!X43:X44) -> 0 | J23: =SUM('Общий чай'!S42:S43)*0.5 -> 0 | L23: =D23+F23+G23+H23+I23+J23-K23 -> 0 | O23: =L23-M23-N23 -> 0
A24: Г | H24: =SUM('крейзи консум новый'!C45:C46) -> 0 | I24: =SUM('крейзи консум новый'!X45:X46) -> 0 | J24: =SUM('Общий чай'!S44:S45)*0.5 -> 0 | L24: =D24+G24+H24+I24+J24-K24 -> 0 | O24: =L24-M24-N24 -> 0
A25: Г | H25: =SUM('крейзи консум новый'!C47:C48) -> 0 | I25: =SUM('крейзи консум новый'!X47:X48) -> 0 | J25: =SUM('Общий чай'!S46:S47)*0.5 -> 0 | L25: =D25+G25+H25+I25+J25-K25 -> 0 | O25: =L25-M25-N25 -> 0
A26: Г | H26: =SUM('крейзи консум новый'!C49:C50) -> 0 | I26: =SUM('крейзи консум новый'!X49:X50) -> 0 | J26: =SUM('Общий чай'!S48:S49)*0.5 -> 0 | L26: =D26+G26+H26+I26+J26-K26 -> 0 | O26: =L26-M26-N26 -> 0
A27: Г | H27: =SUM('крейзи консум новый'!C51:C52) -> 0 | I27: =SUM('крейзи консум новый'!X51:X52) -> 0 | J27: =SUM('Общий чай'!S50:S51)*0.5 -> 0 | L27: =D27+G27+H27+I27+J27-K27 -> 0 | O27: =L27-M27-N27 -> 0
A28: Г | H28: =SUM('крейзи консум новый'!C53:C54) -> 0 | I28: =SUM('крейзи консум новый'!X53:X54) -> 0 | J28: =SUM('Общий чай'!S52:S53)*0.5 -> 0 | L28: =D28+G28+H28+I28+J28-K28 -> 0 | O28: =L28-M28-N28 -> 0
A29: Официанты
A30: Оф | B30: 3 | C30: Каталина | D30: 1500 | F30: 2400 | H30: =SUM('крейзи консум новый'!C56:C57) -> 0 | I30: 1050 | J30: =SUM('Общий чай'!S55:S56)*0.5 -> 1500 | L30: =SUM(D30:J30)-K30 -> 6450 | M30: 1050 | N30: 400 | O30: =L30-M30-N30 -> 5000
A31: Оф | B31: 4 | C31: Ника | D31: 1500 | F31: 2400 | H31: =SUM('крейзи консум новый'!C58:C59) -> 0 | I31: =SUM('крейзи консум новый'!X58:X59) -> 0 | J31: =SUM('Общий чай'!S57:S58)*0.5 -> 1250 | L31: =SUM(D31:J31)-K31 -> 5150 | M31: 750 | N31: 4400 | O31: =L31-M31-N31 -> 0
A32: Оф | H32: =SUM('крейзи консум новый'!C60:C61) -> 0 | I32: =SUM('крейзи консум новый'!X60:X61) -> 0 | J32: =SUM('Общий чай'!S59:S60)*0.5 -> 0 | L32: =SUM(D32:J32)-K32 -> 0 | O32: =L32-M32-N32 -> 0
A33: Оф | H33: =SUM('крейзи консум новый'!C62:C63) -> 0 | I33: =SUM('крейзи консум новый'!X62:X63) -> 0 | J33: =SUM('Общий чай'!S61:S62)*0.5 -> 0 | L33: =SUM(D33:J33)-K33 -> 0 | O33: =L33-M33-N33 -> 0
A34: Оф | H34: =SUM('крейзи консум новый'!C64:C65) -> 0 | I34: =SUM('крейзи консум новый'!X64:X65) -> 0 | J34: =SUM('Общий чай'!S63:S64)*0.5 -> 0 | L34: =SUM(D34:J34)-K34 -> 0 | O34: =L34-M34-N34 -> 0
A35: Оф | H35: =SUM('крейзи консум новый'!C66:C67) -> 0 | I35: =SUM('крейзи консум новый'!X66:X67) -> 0 | J35: =SUM('Общий чай'!S65:S66)*0.5 -> 0 | L35: =SUM(D35:J35)-K35 -> 0 | O35: =L35-M35-N35 -> 0
A36: Оф | H36: =SUM('крейзи консум новый'!C68:C69) -> 0 | I36: =SUM('крейзи консум новый'!X68:X69) -> 0 | J36: =SUM('Общий чай'!S67:S68)*0.5 -> 0 | L36: =SUM(D36:J36)-K36 -> 0 | O36: =L36-M36-N36 -> 0
A37: Оф | H37: =SUM('крейзи консум новый'!C70:C71) -> 0 | I37: =SUM('крейзи консум новый'!X70:X71) -> 0 | J37: =SUM('Общий чай'!S69:S70)*0.5 -> 0 | L37: =SUM(D37:J37)-K37 -> 0 | O37: =L37-M37-N37 -> 0
A38: Хостес
A39: Н | B39: 3 | C39: Влада | D39: 4000 | H39: =SUM('крейзи консум новый'!C73:C74) -> 0 | I39: =SUM('крейзи консум новый'!X73:X74) -> 0 | J39: =SUM('Общий чай'!S72:S73) -> 1000 | L39: =D39+G39+H39+I39+J39-K39 -> 5000 | M39: 1000 | O39: =L39-M39-N39 -> 4000
A40: Н | B40: 4 | C40: Тати | D40: 4000 | H40: =SUM('крейзи консум новый'!C75:C76) -> 0 | I40: =SUM('крейзи консум новый'!X75:X76) -> 0 | J40: =SUM('Общий чай'!S74:S75) -> 1500 | L40: =D40+G40+H40+I40+J40-K40 -> 5500 | M40: 1500 | N40: 3000 | O40: =L40-M40-N40 -> 1000
...

Sheet крейзи консум новый
A1: ДАТА | K1: АДМИНИСТРАТОР
A2: № | C2: СУММА CRAZY | D2: ПОЗИЦИИ ПО CRAZY | X2: СУММА КОНСУМАЦИИ | Y2: ПОЗИЦИИ ПО КОНСУМАЦИИ
A3: Танцовщицы | Y3: Танцовщицы
A4: Д | B4: =SUM('Лист выплат'!B3) -> 3 | C4: =SUM(D4:W4) -> 5375 | D4: 1250 | E4: 1000 | F4: 2000 | G4: 1125 | X4: =SUM(Y4:AR4) -> 1200 | Y4: 600 | Z4: 600
D5: л26 | E5: л27 | F5: л28 | G5: Л26 | Y5: со4 | Z5: со4 | AT5: ЛАЙФ-60%
A6: Д | B6: =SUM('Лист выплат'!B4) -> 5 | C6: =SUM(D6:W6) -> 16200 | D6: 1125 | E6: 900 | F6: 1800 | G6: 4050 | H6: 2700 | I6: 1800 | J6: 1125 | K6: 900 | L6: 1800 | X6: =SUM(Y6:AR6) -> 3800 | Y6: 3200 | Z6: 600
D7: Л26 | E7: Л27 | F7: Л28 | G7: л25 | H7: л33 | I7: л34 | J7: Л26 | K7: Л27 | L7: Л28 | Y7: в4 | Z7: со4
A8: Д | B8: =SUM('Лист выплат'!B5) -> 9 | C8: =SUM(D8:W8) -> 8550 | D8: 4050 | E8: 2700 | F8: 1800 | X8: =SUM(Y8:AR8) -> 300 | Y8: 300
D9: л25 | E9: л33 | F9: л34 | Y9: со1
A10: Д | B10: =SUM('Лист выплат'!B6) -> 11 | C10: =SUM(D10:W10) -> 20450 | D10: 1125 | E10: 900 | F10: 1800 | G10: 1250 | H10: 1000 | I10: 2000 | J10: 1125 | K10: 900 | L10: 1800 | M10: 4050 | N10: 2700 | O10: 1800 | X10: =SUM(Y10:AR10) -> 600 | Y10: 600
D11: Л26 | E11: Л27 | F11: Л28 | G11: л26 | H11: л27 | I11: л28 | J11: Л26 | K11: Л27 | L11: Л28 | M11: л25 | N11: л33 | O11: л34 | Y11: со4
A12: Д | B12: =SUM('Лист выплат'!B7) -> 18 | C12: =SUM(D12:W12) -> 34200 | D12: 4050 | E12: 2700 | F12: 1800 | G12: 4050 | H12: 2700 | I12: 1800 | J12: 4050 | K12: 2700 | L12: 1800 | M12: 4050 | N12: 2700 | O12: 1800 | X12: =SUM(Y12:AR12) -> 0
D13: л25 | E13: л33 | F13: л34 | G13: л25 | H13: л33 | I13: л34 | J13: л25 | K13: л33 | L13: л34 | M13: л25 | N13: л33 | O13: л34
A14: Д | B14: =SUM('Лист выплат'!B8) -> 21 | C14: =SUM(D14:W14) -> 0 | X14: =SUM(Y14:AR14) -> 2280 | Y14: 300 | Z14: 300 | AA14: 600 | AB14: 540 | AC14: 540
Y15: со1 | Z15: со1 | AA15: со4 | AB15: со4 | AC15: со4
A16: Д | B16: =SUM('Лист выплат'!B9) -> 66 | C16: =SUM(D16:W16) -> 23850 | D16: 1125 | E16: 900 | F16: 1800 | G16: 1125 | H16: 900 | I16: 1800 | J16: 4050 | K16: 2700 | L16: 1800 | M16: 1125 | N16: 900 | O16: 1800 | P16: 1125 | Q16: 900 | R16: 1800 | X16: =SUM(Y16:AR16) -> 1740 | Y16: 600 | Z16: 600 | AA16: 540
D17: Л26 | E17: Л27 | F17: Л28 | G17: Л26 | H17: Л27 | I17: Л28 | J17: л25 | K17: л33 | L17: л34 | M17: Л26 | N17: Л27 | O17: Л28 | P17: Л26 | Q17: Л27 | R17: Л28 | Y17: со4 | Z17: со4 | AA17: со4
A18: Д | B18: =SUM('Лист выплат'!B10) -> 0 | C18: =SUM(D18:W18) -> 0 | X18: =SUM(Y18:AR18) -> 0
A20: Д | B20: =SUM('Лист выплат'!B11) -> 0 | C20: =SUM(D20:W20) -> 0 | X20: =SUM(Y20:AR20) -> 0
A22: Д | B22: =SUM('Лист выплат'!B12) -> 0 | C22: =SUM(D22:W22) -> 0 | X22: =SUM(Y22:AR22) -> 0
A24: Д | B24: =SUM('Лист выплат'!B13) -> 0 | C24: =SUM(D24:W24) -> 0 | X24: =SUM(Y24:AR24) -> 0
A26: Д | B26: =SUM('Лист выплат'!B14) -> 0 | C26: =SUM(D26:W26) -> 0 | X26: =SUM(Y26:AR26) -> 0
A28: Д | B28: =SUM('Лист выплат'!B15) -> 0 | C28: =SUM(D28:W28) -> 0 | X28: =SUM(Y28:AR28) -> 0
A30: Д | B30: =SUM('Лист выплат'!B16) -> 0 | C30: =SUM(D30:W30) -> 0 | X30: =SUM(Y30:AR30) -> 0
A32: Д | B32: =SUM('Лист выплат'!B17) -> 0 | C32: =SUM(D32:W32) -> 0 | X32: =SUM(Y32:AR32) -> 0
A34: Патигерл | Y34: Патигерл
A35: Г | B35: =SUM('Лист выплат'!B19) -> 0 | C35: =SUM(D35:W35) -> 0 | X35: =SUM(Y35:AR35) -> 0
A37: Г | B37: =SUM('Лист выплат'!B20) -> 0 | C37: =SUM(D37:W37) -> 0 | X37: =SUM(Y37:AR37) -> 0
A39: Г | B39: =SUM('Лист выплат'!B21) -> 0 | C39: =SUM(D39:W39) -> 0 | X39: =SUM(Y39:AR39) -> 0
A41: Г | B41: =SUM('Лист выплат'!B22) -> 0 | C41: =SUM(D41:W41) -> 0 | X41: =SUM(Y41:AR41) -> 0
A43: Г | B43: =SUM('Лист выплат'!B23) -> 0 | C43: =SUM(D43:W43) -> 0 | X43: =SUM(Y43:AR43) -> 0
A45: Г | B45: =SUM('Лист выплат'!B24) -> 0 | C45: =SUM(D45:W45) -> 0 | X45: =SUM(Y45:AR45) -> 0
A47: Г | B47: =SUM('Лист выплат'!B25) -> 0 | C47: =SUM(D47:W47) -> 0 | X47: =SUM(Y47:AR47) -> 0
A49: Г | B49: =SUM('Лист выплат'!B26) -> 0 | C49: =SUM(D49:W49) -> 0 | X49: =SUM(Y49:AR49) -> 0
A51: Г | B51: =SUM('Лист выплат'!B27) -> 0 | C51: =SUM(D51:W51) -> 0 | X51: =SUM(Y51:AR51) -> 0
A53: Г | B53: =SUM('Лист выплат'!B28) -> 0 | C53: =SUM(D53:W53) -> 0 | X53: =SUM(Y53:AR53) -> 0
B55: Официанты | Y55: Официанты
A56: Оф | B56: =SUM('Лист выплат'!B30) -> 3 | C56: =SUM(D56:W56) -> 0 | X56: =SUM(Y56:AR56) -> 1080 | Y56: 540 | Z56: 540
Y57: со4 | Z57: со4
A58: Оф | B58: =SUM('Лист выплат'!B31) -> 4 | C58: =SUM(D58:W58) -> 0 | X58: =SUM(Y58:AR58) -> 0
...

Sheet Общий чай
A1: CARTEL | F1: ДАТА: | H1: АДМИНИСТРАТОР: | M1: ВЕДОМОСТЬ ПО ОБЩЕМУ ЧАЮ | S1: Итого:
A2: Танцовщицы
A3: Д | B3: =SUM('Лист выплат'!B3) -> 3 | S3: =SUM(C3:R4) -> 0
A5: Д | B5: =SUM('Лист выплат'!B4) -> 5 | C5: 1000 | D5: 500 | E5: 3000 | F5: 500 | S5: =SUM(C5:R6) -> 5000
A7: Д | B7: =SUM('Лист выплат'!B5) -> 9 | S7: =SUM(C7:R8) -> 0
A9: Д | B9: =SUM('Лист выплат'!B6) -> 11 | C9: 1000 | D9: 3000 | E9: 2000 | F9: 1000 | S9: =SUM(C9:R10) -> 7000
A11: Д | B11: =SUM('Лист выплат'!B7) -> 18 | C11: 1000 | S11: =SUM(C11:R12) -> 1000
A13: Д | B13: =SUM('Лист выплат'!B8) -> 21 | C13: 1000 | D13: 2500 | E13: 1000 | F13: 5000 | S13: =SUM(C13:R14) -> 9500
A15: Д | B15: =SUM('Лист выплат'!B9) -> 66 | C15: 1000 | D15: 1000 | E15: 500 | F15: 2000 | G15: 2500 | H15: 1000 | I15: 4000 | J15: 2000 | S15: =SUM(C15:R16) -> 14000
A17: Д | B17: =SUM('Лист выплат'!B10) -> 0 | S17: =SUM(C17:R18) -> 0
A19: Д | B19: =SUM('Лист выплат'!B11) -> 0 | S19: =SUM(C19:R20) -> 0
A21: Д | B21: =SUM('Лист выплат'!B12) -> 0 | S21: =SUM(C21:R22) -> 0
A23: Д | B23: =SUM('Лист выплат'!B13) -> 0 | S23: =SUM(C23:R24) -> 0
A25: Д | B25: =SUM('Лист выплат'!B13) -> 0 | S25: =SUM(C25:R26) -> 0
A27: Д | B27: =SUM('Лист выплат'!B15) -> 0 | S27: =SUM(C27:R28) -> 0
A29: Д | B29: =SUM('Лист выплат'!B16) -> 0 | S29: =SUM(C29:R30) -> 0
A31: Д | B31: =SUM('Лист выплат'!B17) -> 0 | S31: =SUM(C31:R32) -> 0
A33: Патигерл
A34: Г | B34: =SUM('Лист выплат'!B19) -> 0 | S34: =SUM(C34:R35) -> 0
A36: Г | B36: =SUM('Лист выплат'!B20) -> 0 | S36: =SUM(C36:R37) -> 0
A38: Г | B38: =SUM('Лист выплат'!B21) -> 0 | S38: =SUM(C38:R39) -> 0
A40: Г | B40: =SUM('Лист выплат'!B22) -> 0 | S40: =SUM(C40:R41) -> 0
A42: Г | B42: =SUM('Лист выплат'!B23) -> 0 | S42: =SUM(C42:R43) -> 0
A44: Г | B44: =SUM('Лист выплат'!B24) -> 0 | S44: =SUM(C44:R45) -> 0
A46: Г | B46: =SUM('Лист выплат'!B25) -> 0 | S46: =SUM(C46:R47) -> 0
A48: Г | B48: =SUM('Лист выплат'!B26) -> 0 | S48: =SUM(C48:R49) -> 0
A50: Г | B50: =SUM('Лист выплат'!B27) -> 0 | S50: =SUM(C50:R51) -> 0
A52: Г | B52: =SUM('Лист выплат'!B28) -> 0 | S52: =SUM(C52:R53) -> 0
A54: Официанты
A55: Оф | B55: =SUM('Лист выплат'!B30) -> 3 | C55: 2000 | D55: 1000 | S55: =SUM(C55:R56) -> 3000
A57: Оф | B57: =SUM('Лист выплат'!B31) -> 4 | C57: 1000 | D57: 1500 | S57: =SUM(C57:R58) -> 2500
A59: Оф | B59: =SUM('Лист выплат'!B32) -> 0 | S59: =SUM(C59:R60) -> 0
A61: Оф | B61: =SUM('Лист выплат'!B33) -> 0 | S61: =SUM(C61:R62) -> 0
A63: Оф | B63: =SUM('Лист выплат'!B34) -> 0 | S63: =SUM(C63:R64) -> 0
A65: Оф | B65: =SUM('Лист выплат'!B35) -> 0 | S65: =SUM(C65:R66) -> 0
A67: Оф | B67: =SUM('Лист выплат'!B36) -> 0 | S67: =SUM(C67:R68) -> 0
A69: Оф | B69: =SUM('Лист выплат'!B37) -> 0 | S69: =SUM(C69:R70) -> 0
A71: Хостес
A72: Н | B72: =SUM('Лист выплат'!B39) -> 3 | C72: 500 | D72: 500 | S72: =SUM(C72:R73) -> 1000
A74: Н | B74: =SUM('Лист выплат'!B40) -> 4 | C74: 500 | D74: 1000 | S74: =SUM(C74:R75) -> 1500
...

Sheet Штрафы
D1: ВЕДОМОСТЬ ПО ШТРАФАМ
A3: CARTEL | C3: ДАТА: | D3: АДМИНИСТРАТОР:
A5: № | B5: ФИО и ДОЛЖНОСТЬ | C5: ПРИЧИНА ШТРАФА | D5: СУММА | E5: ПОДПИСЬ ОШТРАФОВАННОГО
D20: ИТОГО:
A21: Подпись АДМИНИСТРАТОРА:

Sheet Промоутеры
A1: Дата: 01.11 Админ:
A3: № | B3: Имя | C3: Ставка | D3: Гостей за смену | F3: Сумма общая | G3: Штраф | H3: К выплате | I3: Остаток
D4: кол-во | E4: сумма
A5: Р1 | B5: Дима | C5: 1000 | D5: 5.5 | E5: 12000 | F5: =SUM(C5,E5) -> 13000 | I5: =F5-G5-H5 -> 13000
A6: Р9 | B6: Рома | C6: 1000 | D6: 2 | E6: 4000 | F6: =SUM(C6,E6) -> 5000 | I6: =F6-G6-H6 -> 5000
A7: Р10 | B7: Дима | C7: 1000 | F7: =SUM(C7,E7) -> 1000 | I7: =F7-G7-H7 -> 1000
A8: Р15 | B8: Гриша | C8: 1000 | D8: 4.5 | E8: 9000 | F8: =SUM(C8,E8) -> 10000 | I8: =F8-G8-H8 -> 10000
A9: Р17 | B9: Ильяз | C9: 1000 | D9: 11 | E9: 19500 | F9: =SUM(C9,E9) -> 20500 | I9: =F9-G9-H9 -> 20500
A10: Р29 | B10: Сергей | C10: 1000 | F10: =SUM(C10,E10) -> 1000 | I10: =F10-G10-H10 -> 1000
F11: =SUM(C11,E11) -> 0 | I11: =F11-G11-H11 -> 0
F12: =SUM(C12,E12) -> 0 | I12: =F12-G12-H12 -> 0
F13: =SUM(C13,E13) -> 0 | I13: =F13-G13-H13 -> 0
F14: =SUM(F5:F13) -> 50500 | I14: =SUM(I5:I13) -> 50500

Sheet Расчетный Карты
A1: Дата: | K1: Управляющий: | AI1: Ведомость Консумационных Карт
A3: № Карты | C3: Сумма Общего Чека | H3: Кол-во Человек | M3: № Карты | O3: Сумма Общего Чека | T3: Кол-во Человек | Y3: № Карты | AA3: Сумма Общего Чека | AF3: Кол-во Человек
A44: Примечание:
AF50: подпись

Sheet Доходы сотрудников
D1: ДАТА: 01.11 | N1: АДМИНИСТРАТОР: А17
B3: № | C3: ФАМИЛИЯ | D3: СТАВКА | E3: 5% ЛМ | F3: 0.05 | G3: ПРОМО | H3: CRAZY MENU | I3: Консумация | J3: ЧАЕВЫЕ | K3: ШТРАФЫ | L3: ИТОГО выплат по смене | M3: ДОЛГ | N3: ДОЛГ НАЛ | O3: ИТОГО К ВЫПЛАТЕ | P3: ПОДПИСЬ РАБОТНИКА
B4: Д3 | C4: Даша
B5: Д5 | C5: Софья
B6: Д9 | C6: Лилит
B7: Д11 | C7: Дана
B8: Д18 | C8: Аннет
B9: Д21 | C9: Банни
B10: Д66 | C10: Алиса
B11: Д6 | C11: Саманта
B13: Оф3 | C13: Каталина
B14: Оф4 | C14: Ника
B16: Н3 | C16: Влада
B17: Н4 | C17: Тати
... B22: К21 | C22: Маратик
B23: Дж14 | C23: Сергей | D23: 3000
B25: М69 | C25: Марина
B26: А17 | C26: Юля
B28: СБ | C28: Женя Егоров | D28: 4000
B29: СБ | C29: Дима Песков | D29: 4000
B30: СБ | C30: Денис Ермаков | D30: 4000
C32: уборщица | D32: 2000
C38: ИТОГО:
B39: Подпись АДМИНИСТРАТОРА:
